test_4 error: TypeError. Inputs: (10, '50'), {}Вызов функции 'test_4' с аргументами: (), {}
Функция 'test_4' вызвала исключение: TypeError
Вызов функции 'test_4' с аргументами: (), {}
Функция 'test_4' вызвала исключение: TypeError
